<?xml version="1.0" encoding="utf-8"?>
<robot name="inovo_prd_medium">
	<link name="base">
		<visual>
			<origin xyz="0 0 0" rpy="0 0 0" />
			<geometry>
				<mesh filename="package://inovo_description/meshes/prd/J1.dae" />
			</geometry>
		</visual>
		<collision>
			<origin xyz="0 0 0.09" rpy="0 0 0" />
			<geometry>
				<cylinder radius="0.08" length="0.18" />
			</geometry>
		</collision>
		<inertial>
			<origin xyz="0.0 0.0 0.0873" rpy="0 0 0" />
			<mass value="4.696" />
			<inertia ixx="0.0162" iyy="0.0162" izz="0.0138" ixy="-0.00037" ixz="-0.000216" iyz="0.00031" />
		</inertial>
	</link>
	<joint name="j1" type="continuous">
		<axis xyz="0 0 1" />
		<parent link="base" />
		<child link="shoulder" />
		<origin xyz="0 0 0.26022" rpy="0 0 0" />
		<dynamics friction="0.0" damping="0.0" />
		<limit effort="3.0" velocity="1.8" />
	</joint>
	<link name="shoulder">
		<visual>
			<origin xyz="0 0 0" rpy="0 0 0" />
			<geometry>
				<mesh filename="package://inovo_description/meshes/prd/J2.dae" />
			</geometry>
		</visual>
		<collision>
			<origin xyz="-0.005 0 0" rpy="0 1.57079632679 0" />
			<geometry>
				<cylinder radius="0.08" length="0.17" />
			</geometry>
		</collision>
		<inertial>
			<origin xyz="0.01745 0.0 -0.03032" rpy="0 0 0" />
			<mass value="5.24" />
			<inertia ixx="0.01699" ixy="0.0" ixz="-0.0005" iyy="0.01758" iyz="0.0" izz="0.01251" />
		</inertial>
	</link>
	<joint name="j2" type="continuous">
		<axis xyz="0 0 1" />
		<parent link="shoulder" />
		<child link="shoulder_output" />
		<origin xyz="0.1335 0 0" rpy="0 4.7123889804 3.14159265359" />
		<dynamics friction="0.0" damping="0.0" />
		<limit effort="4.0" velocity="1.8" />
	</joint>
	<link name="shoulder_output">
		<visual>
			<origin xyz="0 0 0" rpy="0 4.71238 3.1415" />
			<geometry>
				<mesh filename="package://inovo_description/meshes/prd/J2_1.dae" />
			</geometry>
		</visual>
		<collision>
			<origin xyz="0 0 0.002" rpy="0 0 0" />
			<geometry>
				<cylinder radius="0.08" length="0.11" />
			</geometry>
		</collision>
		<inertial>
			<origin xyz="0.00803 0.0 -0.0271" rpy="0 0 0" />
			<mass value="2.243" />
			<inertia ixx="0.00579" iyy="0.00653" izz="0.00604" ixy="0.0" ixz="0.000577" iyz="0.0" />
		</inertial>
	</link>
	<joint name="shoulder_output_coupling" type="fixed">
		<parent link="shoulder_output" />
		<child link="upper_arm_link" />
		<origin xyz="0.07975 0.0 0.0" rpy="3.14159265359 -1.57079632679 0" />
	</joint>
	<link name="upper_arm_link">
		<visual>
			<geometry>
				<mesh filename="package://inovo_description/meshes/prd/TUBE_300.dae" />
			</geometry>
		</visual>
		<collision>
			<origin xyz="0 0 0.165" rpy="0 0 0" />
			<geometry>
				<cylinder radius="0.05" length="0.33" />
			</geometry>
		</collision>
		<inertial>
			<origin xyz="0.0 0.0 0.12513" rpy="0 0 0" />
			<mass value="1.084" />
			<inertia ixx="0.0151" iyy="0.0151" izz="0.00137" ixy="0.0" ixz="0.0" iyz="0.0005" />
		</inertial>
	</link>
	<joint name="upper_arm_coupling" type="fixed">
		<parent link="upper_arm_link" />
		<child link="elbow" />
		<origin xyz="0 0 0.3004" rpy="0 0 0" />
	</joint>
	<link name="elbow">
		<visual>
			<origin xyz="0 0 0.09025" rpy="3.14 3.14 3.14" />
			<geometry>
				<mesh filename="package://inovo_description/meshes/prd/J3.dae" />
			</geometry>
		</visual>
		<collision>
			<origin xyz="0 0 0.09" rpy="0 1.57 0" />
			<geometry>
				<cylinder radius="0.06" length="0.14" />
			</geometry>
		</collision>
		<inertial>
			<origin xyz="-0.01456 0.0 0.0112" rpy="0 0 0" />
			<mass value="2.58" />
			<inertia ixx="0.00555" ixy="0.0" ixz="-0.00039" iyy="0.0066" iyz="0.0" izz="0.00459" />
		</inertial>
	</link>
	<joint name="j3" type="continuous">
		<axis xyz="0 0 1" />
		<parent link="elbow" />
		<child link="wrist_a" />
		<origin xyz="0 0 0.09025" rpy="0 -1.57079632679 0" />
		<dynamics friction="0.0" damping="0.0" />
		<limit effort="10.0" velocity="2.5" />
	</joint>
	<link name="wrist_a">
		<visual>
			<origin xyz="0 0 0.1335" rpy="0 1.57 0" />
			<geometry>
				<mesh filename="package://inovo_description/meshes/prd/J4.dae" />
			</geometry>
		</visual>
		<collision>
			<origin xyz="-0.013 0 0.13" rpy="0 1.57 0" />
			<geometry>
				<cylinder radius="0.06" length="0.15" />
			</geometry>
		</collision>
		<inertial>
			<origin xyz="0.0 0.0 0.1109" rpy="0 0 0" />
			<mass value="2.582" />
			<inertia ixx="0.00464" ixy="0.0" ixz="-0.00" iyy="0.00631" iyz="0.0" izz="0.00523" />
		</inertial>
	</link>
	<joint name="j4" type="continuous">
		<axis xyz="0 0 1" />
		<parent link="wrist_a" />
		<child link="wrist_a_output" />
		<origin xyz="0 0 0.1335" rpy="0 -1.57079632679 3.141592653590" />
		<dynamics friction="0.0" damping="0.0" />
		<limit effort="10.0" velocity="2.6" />
	</joint>
	<link name="wrist_a_output">
		<visual>
			<origin xyz="0 0 0.0647" rpy="0 0 0" />
			<geometry>
				<mesh filename="package://inovo_description/meshes/prd/J4_1.dae" />
			</geometry>
		</visual>
		<collision>
			<origin xyz="0 0 0.08" rpy="0 0 0" />
			<geometry>
				<cylinder radius="0.06" length="0.025" />
			</geometry>
		</collision>
		<inertial>
			<origin xyz="0.0 0.0 0.05836" rpy="0 0 0" />
			<mass value="0.686" />
			<inertia ixx="0.000858" ixy="0.0" ixz="0.0" iyy="0.000856" iyz="0.0" izz="0.000725" />
		</inertial>
	</link>
	<joint name="wrist_a_output_coupling" type="fixed">
		<parent link="wrist_a_output" />
		<child link="forearm" />
		<origin xyz="0 0 0.09477" rpy="0 0 3.141592653590" />
	</joint>
	<link name="forearm">
		<visual>
			<geometry>
				<mesh filename="package://inovo_description/meshes/prd/TUBE_120.dae" />
			</geometry>
		</visual>
		<collision>
			<origin xyz="0 0 0.05" rpy="0 0 0" />
			<geometry>
				<cylinder radius="0.06" length="0.14" />
			</geometry>
		</collision>
		<inertial>
			<origin xyz="0.0 0.0 0.04948" rpy="0 0 0" />
			<mass value="0.834" />
			<inertia ixx="0.0021" ixy="0.0" ixz="0.0" iyy="0.00204" iyz="0.0" izz="0.00095" />
		</inertial>
	</link>
	<joint name="forearm_coupling" type="fixed">
		<parent link="forearm" />
		<child link="wrist_b" />
		<origin xyz="0 0 0.1196" rpy="0 0 0" />
	</joint>
	<link name="wrist_b">
		<visual>
			<origin xyz="0 0 0.30523" rpy="0 0 0" />
			<geometry>
				<mesh filename="package://inovo_description/meshes/prd/J5.dae" />
			</geometry>
		</visual>
		<collision>
			<origin xyz="0 0 0.30523" rpy="0 0 0" />
			<geometry>
				<mesh filename="package://inovo_description/meshes/prd/J5_collision.stl" />
			</geometry>
		</collision>
		<inertial>
			<origin xyz="0.07445 0.0 0.21491" rpy="0 0 0" />
			<mass value="2.187" />
			<inertia ixx="0.035951" ixy="0.0" ixz="0.0116" iyy="0.0407" iyz="0.0" izz="0.00685" />
		</inertial>
	</link>
	<joint name="j5" type="continuous">
		<axis xyz="0 0 1" />
		<parent link="wrist_b" />
		<child link="wrist_c" />
		<origin xyz="0 0 0.30523" rpy="0 -1.5707963267908 0" />
		<dynamics friction="0.0" damping="0.0" />
		<limit effort="20.0" velocity="3.3" />
	</joint>
	<link name="wrist_c">
		<visual>
			<origin xyz="0 0 0" rpy="0 1.5707 0" />
			<geometry>
				<mesh filename="package://inovo_description/meshes/prd/J6.dae" />
			</geometry>
		</visual>
		<collision>
			<origin xyz="-0.02 0 0.0" rpy="0 1.57 0" />
			<geometry>
				<cylinder radius="0.045" length="0.14" />
			</geometry>
		</collision>
		<inertial>
			<origin xyz="0.01238 0.0 0.00431" rpy="0 0 0" />
			<mass value="1.933" />
			<inertia ixx="0.0029" ixy="0.0" ixz="-0.000431" iyy="0.00357" iyz="0.0" izz="0.00235" />
		</inertial>
	</link>
	<joint name="j6" type="continuous">
		<axis xyz="0 0 1" />
		<parent link="wrist_c" />
		<child link="wrist_c_output" />
		<origin xyz="0 0 0.0" rpy="0 -1.5707963267908 3.141592653590" />
		<dynamics friction="0.0" damping="0.0" />
		<limit effort="25.0" velocity="3.3" />
	</joint>
	<link name="wrist_c_output">
		<visual>
			<origin xyz="0 0 0.0556" rpy="0 1.57 0" />
			<geometry>
				<mesh filename="package://inovo_description/meshes/prd/J6_1.dae" />
			</geometry>
		</visual>
		<collision>
			<origin xyz="0 0 0.075" rpy="0 0 0" />
			<geometry>
				<cylinder radius="0.045" length="0.035" />
			</geometry>
		</collision>
		<inertial>
			<origin xyz="-0.00145 0.0 0.06063" rpy="0 0 0" />
			<mass value="0.38" />
			<inertia ixx="0.000397" ixy="0.0" ixz="0.0" iyy="0.000417" iyz="0.0" izz="0.000244" />
		</inertial>
	</link>
	<joint name="flange_coupling" type="fixed">
		<parent link="wrist_c_output" />
		<child link="flange" />
		<origin xyz="0 0 0.0926" rpy="0 0 0" />
	</joint>
	<link name="flange" />
</robot>