<?xml version="1.0" encoding="utf-8" ?>
<fragment>
	<link name="{{prefix}}_wrist_b">
		<visual>
			<origin xyz="0 0 0" rpy="0 1.5707 0" />
			<geometry>
				<mesh filename="package://inovo_description/meshes/prd/J6.dae" />
			</geometry>
		</visual>
		<collision name="{{prefix}}_wrist_b">
			<origin xyz="-0.02 0 0.0" rpy="0 1.57 0" />
			<geometry>
				<cylinder radius="0.045" length="0.14"/>
			</geometry>
		</collision>
		<inertial>
			<origin xyz="0.01238 0.0 0.00431" rpy="0 0 0" />
			<mass value="1.933" />
			<inertia ixx="0.0029" ixy="0.0" ixz="-0.000431" iyy="0.00357" iyz="0.0" izz="0.00235" />
		</inertial>
	</link>
	<joint name="{{prefix}}" type="continuous">
		<axis xyz="0 0 1" />
		<parent link="{{prefix}}_wrist_b" />
		<child link="{{prefix}}_prd1192" />
		<origin xyz="0 0 0.0" rpy="0 -1.5707963267908 3.141592653590" />
		<dynamics friction="{{friction}}" damping="{{damping}}" />
		<limit effort="25.0" velocity="3.3" />
	</joint>
	<link name="{{prefix}}_prd1192">
		<visual>
			<origin xyz="0 0 0.0556" rpy="0 1.57 0" />
			<geometry>
				<mesh filename="package://inovo_description/meshes/prd/J6_1.dae" />
			</geometry>
		</visual>
		<collision name="{{prefix}}_prd1192">
			<origin xyz="0 0 0.075" rpy="0 0 0" />
			<geometry>
				<cylinder radius="0.045" length="0.035"/>
			</geometry>
		</collision>
		<inertial>
			<origin xyz="-0.00145 0.0 0.06063" rpy="0 0 0" />
			<mass value="0.38" />
			<inertia ixx="0.000397" ixy="0.0" ixz="0.0" iyy="0.000417" iyz="0.0" izz="0.000244" />
		</inertial>
	</link>
	<joint name="{{prefix}}_prd1190_fixed" type="fixed">
		<parent link="{{prefix}}_prd1192" />
		<child link="{{child_link}}" />
		<origin xyz="0 0 0.0926" rpy="0 0 0" />
	</joint>
</fragment>
