<?xml version="1.0" encoding="utf-8" ?>
<fragment>
	<link name="{{prefix}}_jlink">
		<visual>
				<origin xyz="0 0 0.30523" rpy="0 0 0" />
				<geometry>
					<mesh filename="package://inovo_description/meshes/prd/J5.dae" />
				</geometry>
			</visual>
			<collision>
				<origin xyz="0 0 0.30523" rpy="0 0 0" />
				<geometry>
					<mesh filename="package://inovo_description/meshes/prd/J5_collision.stl" />
				</geometry>
			</collision>
		<inertial>
			<origin xyz="0.07445 0.0 0.21491" rpy="0 0 0" />
			<mass value="2.187" />
			<inertia ixx="0.035951" ixy="0.0" ixz="0.0116" iyy="0.0407" iyz="0.0" izz="0.00685" />
		</inertial>
	</link>
	<joint name="{{prefix}}" type="continuous">
		<axis xyz="0 0 1" />
		<parent link="{{prefix}}_jlink" />
		<child link="{{child_link}}" />
		<origin xyz="0 0 0.30523" rpy="0 -1.5707963267908 0" />
		<dynamics friction="{{friction}}" damping="{{damping}}" />
		<limit effort="20.0" velocity="3.3" />
	</joint>
</fragment>
