<?xml version="1.0" encoding="utf-8" ?>
<fragment>
	<link name="{{prefix}}_base">
		<visual>
			<origin xyz="0 0 0" rpy="0 0 0"/>
			<geometry>
				<mesh filename="package://inovo_description/meshes/prd/J1.dae" />
			</geometry>
		</visual>

		<collision name="{{prefix}}_base">
			<origin xyz="0 0 0.09" rpy="0 0 0" />
			<geometry>
				<cylinder radius="0.08" length="0.18"/>
			</geometry>
		</collision>
		<inertial>
			<origin xyz="0.0 0.0 0.0873" rpy="0 0 0" />
			<mass value="4.696" />
			<inertia ixx="0.0162" iyy="0.0162" izz="0.0138" ixy="-0.00037" ixz="-0.000216" iyz="0.00031" />
		</inertial>
	</link>
	<joint name="{{prefix}}" type="continuous">
		<axis xyz="0 0 1" />
		<parent link="{{prefix}}_base" />
		<child link="{{child_link}}" />
		<origin xyz="0 0 0.26022" rpy="0 0 0" />
		<dynamics friction="{{friction}}" damping="{{damping}}" />
		<limit effort="3.0" velocity="1.8" />
		<!-- "effort abused for acceleration while we don't have a torque limited motion planner"-->
	</joint>
</fragment>
