<?xml version="1.0" encoding="utf-8" ?>
<fragment>
	<link name="{{prefix}}_elbow_output">
		<visual>
			<origin xyz="0 0 0.1335" rpy="0 1.57 0"/>
			<geometry>
				<mesh filename="package://inovo_description/meshes/prd/J4.dae" />
			</geometry>
		</visual>
		<collision name="{{prefix}}_elbow_output">
			<origin xyz="-0.013 0 0.13" rpy="0 1.57 0" />
			<geometry>
				<cylinder radius="0.06" length="0.15"/>
			</geometry>
		</collision>
		<inertial>
			<origin xyz="0.0 0.0 0.1109" rpy="0 0 0" />
			<mass value="2.582" />
			<inertia ixx="0.00464" ixy="0.0" ixz="-0.00" iyy="0.00631" iyz="0.0" izz="0.00523" />
		</inertial>
	</link>
	<joint name="{{prefix}}" type="continuous">
		<axis xyz="0 0 1"/>
		<parent link="{{prefix}}_elbow_output" />
		<child link="{{prefix}}_forearm" />
		<origin xyz="0 0 0.1335" rpy="0 -1.57079632679 3.141592653590"/>
		<dynamics friction="{{friction}}" damping="{{damping}}" />
		<limit effort="10.0" velocity="2.6" />
	</joint>
	<link name="{{prefix}}_forearm">
		<visual>
			<origin xyz="0 0 0.0647" rpy="0 0 0"/>
			<geometry>
				<mesh filename="package://inovo_description/meshes/prd/J4_1.dae" />
			</geometry>
		</visual>
		<collision name="{{prefix}}_forearm">
			<origin xyz="0 0 0.08" rpy="0 0 0" />
			<geometry>
				<cylinder radius="0.06" length="0.025"/>
			</geometry>
		</collision>
		<inertial>
			<origin xyz="0.0 0.0 0.05836" rpy="0 0 0" />
			<mass value="0.686" />
			<inertia ixx="0.000858" ixy="0.0" ixz="0.0" iyy="0.000856" iyz="0.0" izz="0.000725" />
		</inertial>
	</link>
	<joint name="{{prefix}}_forearm_coupling" type="fixed">
		<parent link="{{prefix}}_forearm" />
		<child link="{{child_link}}" />
		<origin xyz="0 0 {{0.09477 + calibration.0}}" rpy="0 0 3.141592653590"/>
	</joint>
</fragment>
